Workbook

Sheet Survey Outline
A1: Survey Outline — Quantum Robotics (Computing + Cognition)
A2: Paper 1 = scoped quantum-robotics survey (computing + cognition branches). Deep chapter (§6) motivates Paper 2 (quantum cognition model).
A4: # | B4: Section | C4: What to cover | D4: Feeds from (Papers categories) | E4: Priority
A5: 1 | B5: Introduction & Scope | C5: Define quantum robotics; state that scope = quantum-computing + quantum-cognition methods (sensing/metrology surveyed elsewhere, e.g. Yan et al. 2024); contributions & structure | D5: — | E5: Essential
A6: 2 | B6: Background: Quantum Computing Foundations | C6: Qubits, gates, entanglement; key algorithms (Grover, HHL, Shor); quantum walks; enough for a robotics reader | D6: Quantum Computing Foundations; Linear Algebra; Monte Carlo; Graph | E6: Essential
A7: 3 | B7: Quantum Hardware & NISQ Reality Check | C7: Device limits, error rates, decoherence, latency; why real-time robot control is hard today; feasibility | D7: Quantum Hardware & NISQ | E7: Essential
A8: 4 | B8: Quantum Computing Methods in Robotics (by task) | C8: Organise by robotic function: optimization (planning, task allocation), linear algebra (kinematics), search/sampling (navigation), perception, control | D8: Quantum Optimization; Linear Algebra; Monte Carlo; Graph; QML; Sensor Fusion; Control | E8: Core
A9: 5 | B9: Quantum ML, RL & Learning Agents (the bridge) | C9: QML, quantum neural nets, quantum RL, projective simulation, learning agents — links computing to cognition | D9: Quantum ML, RL & Agents; QML | E9: Core
A10: 6 | B10: Quantum Cognition for Robot Decision-Making | C10: Quantum-probability models of decision/judgment; quantum-like agents; apply to robot/autonomous decision — DEEP chapter; identifies the gap | D10: Quantum Cognition (Foundations); Quantum Cognition in Robotics | E10: DEEP → Paper 2
A11: 7 | B11: Supporting Branches (brief) | C11: Quantum sensing/metrology on robots; quantum communication & security for multi-robot/swarm — covered briefly to bound scope | D11: Quantum Cryptography; Communication & Security | E11: Brief
A12: 8 | B12: Quantum-inspired vs Genuinely-Quantum | C12: Dequantization critique; which methods need real quantum hardware vs classical simulation; honest appraisal | D12: Type column; Tang 2019; Cerezo barren plateaus | E12: Critical
A13: 9 | B13: Open Challenges & Future Directions | C13: Synthesise gaps; concrete first problems; motivate the quantum cognition model (Paper 2) as the next step | D13: Gap Relevance = High rows | E13: Essential → Paper 2
A14: 10 | B14: Conclusion | C14: Recap taxonomy, maturity of the field, and the runway to original contributions | D14: — | E14: Essential
A16: SURVEY 1 SCOPE — Quantum Computing in Robotics
A17: Scope | B17: Explores quantum computing methods and their potential applications across the entire robotics domain.
A18: 10 Applications | B18: Optimization (planning, task allocation), machine learning, linear algebra (kinematics/control), search/sampling (navigation), perception, control theory, sensing, cryptography, and hybrid classical-quantum methods.
A19: Promise | B19: Quantum algorithms (Grover, QAOA, VQE, HHL) offer theoretical speedups for robot decision-making, optimization, and perception.
A20: Hardware Reality Check | B20: Addresses NISQ (Noisy Intermediate-Scale Quantum) limitations—current devices have high error rates, short coherence times, and can't run real-time robot control.
A21: Feasibility Assessment | B21: Most quantum applications require fault-tolerant quantum computers (5–10 years away); TODAY's quantum advantage in robotics is limited.
A22: Dequantization Critique | B22: Honest appraisal of Tang (2019) and similar results—some "quantum speedups" can be classically simulated or aren't practically better.
A23: Comparative Analysis | B23: Head-to-head evaluation: quantum vs. classical methods on robot planning, ML, control; shows where quantum truly helps vs. hype.
A24: Audience | B24: Roboticists wondering "Should we invest in quantum?" and quantum computing practitioners exploring applications.
A25: Conclusion | B25: Quantum computing could revolutionize robotics, but that's a 5–10 year horizon. TODAY's practical quantum robotics is limited.
A26: Bridges to Paper 2 | B26: Establishes that of 10 possibilities, only ONE works now without waiting for quantum hardware: quantum cognition.

Sheet Survey 2 Outline
A1: Survey 2 — Quantum Cognition for Robot Decision-Making · 20-Section Outline
A2: Deep-dive companion to Paper 1: quantum cognition is the one application viable TODAY without quantum hardware. ~50–65 pp across 5 parts.
A4: # | B4: Section | C4: Pages | D4: Purpose | E4: Part
A5: PART A — FOUNDATIONS (§1–3)
A6: 1 | B6: Introduction — Why Quantum Cognition Matters for Robotics | C6: 2–3 pp | D6: Motivate the whole survey. Establish why quantum cognition is the ONE viable approach TODAY. | E6: PART A
A7: 2 | B7: Mathematical Preliminaries — Linear Algebra & Hilbert Spaces (for roboticists) | C7: 3–4 pp | D7: Make quantum math accessible to roboticists unfamiliar with quantum formalism. | E7: PART A
A8: 3 | B8: Standardized Terminology — Glossary & Visual Diagrams | C8: 2–3 pp | D8: Prevent confusion. Define key terms consistently. | E8: PART A
A9: PART B — THEORY (§4–6)
A10: 4 | B10: Foundational Theory — Busemeyer, Bruza, Order Effects, Conjunction Fallacy | C10: 5–7 pp | D10: Deep dive on quantum-cognition theory. Show why quantum models fit decision data better than classical. | E10: PART B
A11: 5 | B11: Tier 1 (DEEP) — Perception, Memory, Decision-Making in Robots | C11: 6–8 pp | D11: Show how quantum cognition applies to THREE high-stakes robot problems TODAY. | E11: PART B
A12: 6 | B12: Tier 2 (MEDIUM) — Learning, Planning, Sensor Fusion | C12: 5–6 pp | D12: Show quantum cognition extends to learning agents and multi-sensor coordination. | E12: PART B
A13: PART C — APPLICATIONS & VALIDATION (§7–12)
A14: 7 | B14: Tier 3 (SHALLOW) — Speculation on Multi-Agent, Concept Learning | C14: 3–4 pp | D14: Preview future research. Show quantum cognition could extend further. | E14: PART C
A15: 8 | B15: Prior Work & Positioning | C15: 4–5 pp | D15: Situate this work in the literature. Show it is novel AND well-grounded. | E15: PART C
A16: 9 | B16: Head-to-Head Comparison — Quantum vs. Classical (honest tradeoffs) | C16: 5–6 pp | D16: Don't oversell quantum. Show when classical wins. | E16: PART C
A17: 10 | B17: Experimental Validation Roadmap | C17: 4–5 pp | D17: How to validate quantum cognition on robots. Detailed methodology. | E17: PART C
A18: 11 | B18: Case Studies & Worked Examples | C18: 5–7 pp | D18: Make it concrete. 2–3 detailed scenarios showing quantum cognition in action. | E18: PART C
A19: 12 | B19: Limitations & Failure Modes | C19: 3–4 pp | D19: Be honest. When does quantum cognition NOT help? | E19: PART C
A20: PART D — GROUNDING & IMPLICATIONS (§13–16)
A21: 13 | B21: Assumptions & Caveats | C21: 2–3 pp | D21: What are we assuming? Where are we uncertain? | E21: PART D
A22: 14 | B22: Ethical, Safety, Transparency Implications | C22: 3–4 pp | D22: What are the broader impacts? Who cares? | E22: PART D
A23: 15 | B23: Hardware & Implementation Requirements | C23: 3–4 pp | D23: How to actually build a quantum-cognitive robot? What do we need? | E23: PART D
A24: 16 | B24: Connection to Neuroscience — Is Quantum Cognition Biologically Grounded? | C24: 3–4 pp | D24: Does quantum cognition relate to how brains actually work? | E24: PART D
A25: PART E — INTEGRATION & FUTURE (§17–20)
A26: 17 | B26: Standardized Benchmarks & Reproducibility | C26: 2–3 pp | D26: How will others validate and extend this work? | E26: PART E
A27: 18 | B27: Related Surveys & Unique Contribution | C27: 2–3 pp | D27: What makes this survey novel? | E27: PART E
A28: 19 | B28: Open Problems & Future Research Directions | C28: 3–4 pp | D28: What's next? Where does quantum cognition in robotics go? | E28: PART E
A29: 20 | B29: Conclusion & Vision Statement | C29: 2–3 pp | D29: End on a high note. Recap. Inspire next steps. | E29: PART E
A31: SURVEY 2 SCOPE — Quantum Cognition for Robot Decision-Making
A32: Scope | B32: Deep dive into quantum probability models for autonomous robot decision-making and cognition.
A33: Core Insight | B33: Robots face decision-making problems (fault diagnosis, multi-goal trade-offs, perception under occlusion) that violate classical probability—quantum models fit better.
A34: Foundation | B34: Builds on Busemeyer & Bruza (quantum cognition psychology); shows order effects, conjunction fallacy, and interference explain robot decision failures.
A35: Why Now | B35: This is the ONLY quantum robotics approach viable TODAY—runs on classical computers (no quantum hardware needed).
A36: Key Applications | B36: Perception under sensor ambiguity; memory and fault episode recognition; decision-making under high-dimensional uncertainty; learning agents (projective simulation); sensor fusion with non-independent modalities.
A37: Advantage Over Classical | B37: Captures non-commutative measurements (order matters), entangled correlations, interference effects—outperforms Bayesian nets 15–25% on fault diagnosis.
A38: Ethical Framework | B38: Addresses transparency (amplitudes hard to explain), safety (when to escalate to humans), and accountability (responsibility when decisions fail).
A39: Rigorous Validation | B39: Includes 3 case studies, standardized benchmarks, comparison against Kalman filters & classical RL, and experimental roadmap.
A40: Neuroscience Grounding | B40: Explains why quantum cognition fits human behavioral data without requiring quantum brains; discusses predictive processing + superposition.
A41: Roadmap | B41: Positions quantum cognition as the bridge TODAY until quantum hardware matures; Paper 3 will PROVE it works on LeKiwi robot with real-world faults.

Sheet  Survey 3 Outline
A1: Survey Outline — Meta-Learning Orchestration of Heterogeneous Learning Modalities on Resource-Constrained Robots
A2: Thesis claim: a local LLM learns to allocate compute across four learning modes (vision/epistemic, RL/policy-variance, imitation/behavioural fidelity, fault/recovery) from federated uncertainty signals, improving online via LoRA + replay. §12 is the DEEP chapter (the learned orchestrator = the core novelty).
A4: # | B4: Section | C4: What to cover | D4: Feeds from (Sheet1 categories) | E4: Priority
A5: 1 | B5: Introduction & Scope | C5: Define the problem: adaptive embodied agents on edge hardware. State the thesis, the four learning modes, and the orchestration claim; delimit scope (single robot, on-device, no cloud) and contributions. | D5: — | E5: Essential
A6: 2 | B6: Background: Learning Modalities in Robotics | C6: Primer on the four paradigms (perception, RL, imitation, fault recovery); why each alone is insufficient; the case for composing them. | D6: RL; Imitation; Vision Uncertainty; Fault Adaptation | E6: Essential
A7: 3 | B7: LLMs as Planners & Orchestrators for Embodied Agents | C7: Survey LLM-driven planning/tool-use/agent loops; frozen-LLM coordination as the baseline your learned orchestrator must beat. | D7: LLM Orchestration & Embodied Agents | E7: Core
A8: 4 | B8: VLA & Robot Foundation Models | C8: Generalist/monolithic policies; why huge single models don't fit edge; motivates a small local LLM + modular modalities. | D8: VLA & Robot Foundation Models | E8: Core
A9: 5 | B9: Modality 1 — Vision Perception with Epistemic Uncertainty | C9: How the vision mode produces a calibrated epistemic-uncertainty confidence (MC-dropout, ensembles, evidential); calibration caveats before fusion. | D9: Vision Perception & Epistemic Uncertainty | E9: Core
A10: 6 | B10: Modality 2 — Reinforcement Learning with Policy Variance | C10: RL backbones and how policy/value variance (entropy, ensembles, twin critics) becomes the RL confidence signal. | D10: Reinforcement Learning (Policy & Uncertainty) | E10: Core
A11: 7 | B11: Modality 3 — Imitation with Behavioural Fidelity | C11: LfD methods and how action-distribution spread / reconstruction gives a behavioural-fidelity confidence. | D11: Imitation Learning / Learning from Demonstration | E11: Core
A12: 8 | B12: Modality 4 — Fault Adaptation & Recovery | C12: Detection + recovery methods and how recovery-success rate becomes the fault-mode confidence; closest prior art (online meta-adaptation to damage). | D12: Fault Adaptation & Recovery | E12: Core
A13: 9 | B13: Meta-Learning & Learning-to-Learn (the orchestration backbone) | C13: Meta-learning / meta-RL as the mechanism by which the orchestrator learns *which* modality to invoke and adapts fast. | D13: Meta-Learning / Learning to Learn | E13: Essential
A14: 10 | B14: Uncertainty Fusion & Federated Confidence Signals | C14: How heterogeneous confidences are made comparable and fused into an allocation policy; what 'federated' means here vs classic FL. | D14: Federated Learning & Uncertainty Fusion; Vision Uncertainty | E14: Critical
A15: 11 | B15: On-Device Adaptation: LoRA, Replay & Continual Learning | C15: Online LoRA fine-tuning, replay buffers, and forgetting mitigation under edge memory/compute; feasibility of training on the robot. | D15: Parameter-Efficient & On-Device Learning; Continual Learning & Replay | E15: Essential
A16: 12 | B16: Adaptive Computation, MoE & Modality Routing (DEEP — core novelty) | C16: Learned routing / adaptive compute as the formal lens on the orchestrator; position the thesis as an MoE-over-learners with a learned, uncertainty-gated, compute-budgeted gate. Identifies the gap. | D16: Adaptive Computation, MoE & Routing | E16: DEEP — core contribution
... A19: 15 | B19: Conclusion | C19: Recap the composition novelty (heterogeneous modes + meta-learning orchestration on constrained hardware) and the empirical claims. | D19: — | E19: Essential

Sheet journel and conference list
A1: Target Journals & Conferences — Surveys 1, 2, 3
A2: Survey 1 = Quantum Computing for Autonomous Robotics (SLR) · Survey 2 = Quantum Cognition for Robot Decision-Making · Survey 3 = Meta-Learning Orchestration on Resource-Constrained Robots. Track A = first-choice target, Track B = backup. Fit: High/Medium/Low. Indexing is from general knowledge — confirm on Clarivate Master Journal List and Scopus Sources before submitting.
A4: # | B4: Venue | C4: Type | D4: Publisher | E4: SCIE indexed? | F4: Scopus indexed? | G4: Track | H4: Survey 1 fit | I4: Survey 2 fit | J4: Survey 3 fit | K4: Match key (in Venue col) | L4: Survey 1 papers | M4: Survey 2 papers | N4: Survey 3 papers | O4: Notes
A5: 1 | B5: Journal of Field Robotics | C5: Journal | D5: Wiley | E5: Y | F5: Y | G5: A | H5: Medium | I5: Low | J5: High | K5: Field Robotics | L5: =COUNTIF('Survey 1 Papers'!$E:$E,"*"&$K5&"*") -> 0 | M5: =COUNTIF('Survey 2 Papers'!$E:$E,"*"&$K5&"*") -> 0 | N5: =COUNTIF('Survey 3 Papers'!$E:$E,"*"&$K5&"*") -> 0 | O5: From original list
A6: 2 | B6: IEEE Transactions on Robotics (T-RO) | C6: Journal | D6: IEEE | E6: Y | F6: Y | G6: A | H6: Medium | I6: Medium | J6: High | K6: Transactions on Robotics | L6: =COUNTIF('Survey 1 Papers'!$E:$E,"*"&$K6&"*") -> 0 | M6: =COUNTIF('Survey 2 Papers'!$E:$E,"*"&$K6&"*") -> 0 | N6: =COUNTIF('Survey 3 Papers'!$E:$E,"*"&$K6&"*") -> 0 | O6: From original list; accepts surveys
A7: 3 | B7: International Journal of Robotics Research (IJRR) | C7: Journal | D7: SAGE | E7: Y | F7: Y | G7: A | H7: Medium | I7: Medium | J7: High | K7: Robotics Research | L7: =COUNTIF('Survey 1 Papers'!$E:$E,"*"&$K7&"*") -> 1 | M7: =COUNTIF('Survey 2 Papers'!$E:$E,"*"&$K7&"*") -> 0 | N7: =COUNTIF('Survey 3 Papers'!$E:$E,"*"&$K7&"*") -> 0 | O7: From original list
A8: 4 | B8: Robotics and Computer-Integrated Manufacturing | C8: Journal | D8: Elsevier | E8: Y | F8: Y | G8: A | H8: Medium | I8: Low | J8: Medium | K8: Computer-Integrated Manufacturing | L8: =COUNTIF('Survey 1 Papers'!$E:$E,"*"&$K8&"*") -> 0 | M8: =COUNTIF('Survey 2 Papers'!$E:$E,"*"&$K8&"*") -> 0 | N8: =COUNTIF('Survey 3 Papers'!$E:$E,"*"&$K8&"*") -> 0 | O8: From original list
A9: 5 | B9: Autonomous Robots | C9: Journal | D9: Springer | E9: Y | F9: Y | G9: A | H9: Medium | I9: Medium | J9: High | K9: Autonomous Robots | L9: =COUNTIF('Survey 1 Papers'!$E:$E,"*"&$K9&"*") -> 0 | M9: =COUNTIF('Survey 2 Papers'!$E:$E,"*"&$K9&"*") -> 0 | N9: =COUNTIF('Survey 3 Papers'!$E:$E,"*"&$K9&"*") -> 0 | O9: From original list
A10: 6 | B10: Journal of Intelligent & Robotic Systems | C10: Journal | D10: Springer | E10: Y | F10: Y | G10: B | H10: High | I10: Medium | J10: High | K10: Intelligent & Robotic Systems | L10: =COUNTIF('Survey 1 Papers'!$E:$E,"*"&$K10&"*") -> 0 | M10: =COUNTIF('Survey 2 Papers'!$E:$E,"*"&$K10&"*") -> 0 | N10: =COUNTIF('Survey 3 Papers'!$E:$E,"*"&$K10&"*") -> 0 | O10: From original list
A11: 7 | B11: Robotica | C11: Journal | D11: Cambridge Univ. Press | E11: Y | F11: Y | G11: B | H11: High | I11: Medium | J11: Medium | K11: Robotica | L11: =COUNTIF('Survey 1 Papers'!$E:$E,"*"&$K11&"*") -> 1 | M11: =COUNTIF('Survey 2 Papers'!$E:$E,"*"&$K11&"*") -> 1 | N11: =COUNTIF('Survey 3 Papers'!$E:$E,"*"&$K11&"*") -> 0 | O11: From original list
A12: 8 | B12: Advanced Robotics | C12: Journal | D12: Taylor & Francis | E12: Y | F12: Y | G12: B | H12: Medium | I12: Medium | J12: Medium | K12: Advanced Robotics | L12: =COUNTIF('Survey 1 Papers'!$E:$E,"*"&$K12&"*") -> 0 | M12: =COUNTIF('Survey 2 Papers'!$E:$E,"*"&$K12&"*") -> 0 | N12: =COUNTIF('Survey 3 Papers'!$E:$E,"*"&$K12&"*") -> 0 | O12: From original list
A13: 9 | B13: Intelligent Service Robotics | C13: Journal | D13: Springer | E13: Y | F13: Y | G13: B | H13: Medium | I13: High | J13: Medium | K13: Intelligent Service Robotics | L13: =COUNTIF('Survey 1 Papers'!$E:$E,"*"&$K13&"*") -> 0 | M13: =COUNTIF('Survey 2 Papers'!$E:$E,"*"&$K13&"*") -> 0 | N13: =COUNTIF('Survey 3 Papers'!$E:$E,"*"&$K13&"*") -> 0 | O13: From original list; HRI / decision-making fit for S2
A14: 10 | B14: Sadhana | C14: Journal | D14: Springer (Indian Acad. Sci.) | E14: Y | F14: Y | G14: B | H14: Medium | I14: Low | J14: Low | K14: Sadhana | L14: =COUNTIF('Survey 1 Papers'!$E:$E,"*"&$K14&"*") -> 0 | M14: =COUNTIF('Survey 2 Papers'!$E:$E,"*"&$K14&"*") -> 0 | N14: =COUNTIF('Survey 3 Papers'!$E:$E,"*"&$K14&"*") -> 0 | O14: From original list; broad engineering scope
A15: 11 | B15: Scientific Reports | C15: Journal | D15: Nature Portfolio | E15: Y | F15: Y | G15: B | H15: High | I15: High | J15: Medium | K15: Scientific Reports | L15: =COUNTIF('Survey 1 Papers'!$E:$E,"*"&$K15&"*") -> 8 | M15: =COUNTIF('Survey 2 Papers'!$E:$E,"*"&$K15&"*") -> 8 | N15: =COUNTIF('Survey 3 Papers'!$E:$E,"*"&$K15&"*") -> 0 | O15: From original list; APC applies
A16: 12 | B16: Quantum Machine Intelligence | C16: Journal | D16: Springer | E16: Y (verify) | F16: Y | G16: A | H16: High | I16: High | J16: Low | K16: Quantum Machine Intelligence | L16: =COUNTIF('Survey 1 Papers'!$E:$E,"*"&$K16&"*") -> 2 | M16: =COUNTIF('Survey 2 Papers'!$E:$E,"*"&$K16&"*") -> 2 | N16: =COUNTIF('Survey 3 Papers'!$E:$E,"*"&$K16&"*") -> 0 | O16: Added — published Yan et al. 2024 quantum-robotics review
... A37: 33 | B37: NeurIPS | C37: Conference | D37: NeurIPS Foundation | E37: N/A | F37: Verify | G37: A | H37: Low | I37: Low | J37: High | K37: NeurIPS | L37: =COUNTIF('Survey 1 Papers'!$E:$E,"*"&$K37&"*") -> 1 | M37: =COUNTIF('Survey 2 Papers'!$E:$E,"*"&$K37&"*") -> 3 | N37: =COUNTIF('Survey 3 Papers'!$E:$E,"*"&$K37&"*") -> 22 | O37: Conference

Sheet Paper References
A1: Ref # | B1: Citation | C1: Year | D1: Type | E1: Read status
A2: 1 | B2: S. Thrun, W. Burgard, and D. Fox, Probabilistic Robotics. MIT Press, 2005. | C2: 2005 | D2: Book
A3: 2 | B3: S. M. LaValle, Planning Algorithms. Cambridge University Press, 1998. | C3: 1998 | D3: Book
A4: 3 | B4: S. Karaman and E. Frazzoli, "Sampling-based algorithms for optimal motion planning," Int. J. Robot. Res., vol. 30, no. 7, pp. 846–894, 2011. | C4: 2011 | D4: Journal
A5: 4 | B5: M. A. Nielsen and I. L. Chuang, Quantum Computation and Quantum Information. Cambridge University Press, 2010. | C5: 2010 | D5: Book
A6: 5 | B6: A. Montanaro, "Quantum algorithms: An overview," npj Quantum Inf., vol. 2, p. 15023, 2016. | C6: 2016 | D6: Journal
A7: 6 | B7: F. Yan, A. M. Iliyasu, N. Li, and K. Hirota, "Quantum robotics: A review of emerging trends," Quantum Mach. Intell., vol. 6, no. 2, p. 86, 2024. | C7: 2024 | D7: Journal
A8: 7 | B8: J. Lamm, Quantum Computing for Business. Packt Publishing, 2021. | C8: 2021 | D8: Book
A9: 8 | B9: D. Dong et al., "Quantum control theory and applications," IEEE Trans. Autom. Control, vol. 55, no. 10, pp. 2271–2285, 2010. | C9: 2010 | D9: Journal
A10: 9 | B10: J. Preskill, "Quantum computing in the NISQ era and beyond," Quantum, vol. 2, p. 79, 2018. | C10: 2018 | D10: Journal
A11: 10 | B11: K. Bharti et al., "Noisy intermediate-scale quantum algorithms," Rev. Mod. Phys., vol. 94, p. 015004, 2022. | C11: 2022 | D11: Journal
A12: 11 | B12: F. Arute et al., "Quantum supremacy using a programmable superconducting processor," Nature, vol. 574, pp. 505–510, 2019. | C12: 2019 | D12: Journal
A13: 12 | B13: B. M. Terhal, "Quantum error correction for quantum memories," Rev. Mod. Phys., vol. 87, p. 307, 2015. | C13: 2015 | D13: Journal
... A63: 62 | B63: M. Cerezo et al., "Variational quantum algorithms," Nature Rev. Phys., vol. 3, pp. 625–643, 2021. | C63: 2021 | D63: Journal

Sheet quantum_computing_Papers
A1: Category | B1: Author | C1: Year | D1: Title | E1: Venue | F1: Relevance | G1: Status | H1: URL | I1: Importance | J1: Robotics Function | K1: Type | L1: Serves | M1: Gap Relevance | N1: Evidence Type | O1: Open Question / Limitation (for survey) | P1: Outline § | Q1: Read status | R1: Key takeaway / notes | S1: Read for Survey § | T1: Survey read role
A2: Quantum Optimization | B2: Farhi, E., Goldstone, J., Gutmann, S. | C2: 2014 | D2: A Quantum Approximate Optimization Algorithm | E2: arXiv:1411.4028 | F2: Foundational QAOA paper; introduces variational quantum circuits for combinatorial optimization | G2: Open Access | H2: https://arxiv.org/abs/1411.4028 | I2: ★★★★★ | J2: Planning & Control | K2: Quantum | L2: Survey | M2: Low | N2: Algorithmic / theoretical | O2: Does it outperform classical optimization for realistic robot problems? | P2: §4 | Q2: To read | S2: §4 | T2: Core
A3: Quantum Optimization | B3: Hadfield, S., Wang, Z., O'Gorman, B., et al. | C3: 2019 | D3: From the Ising model to QAOA: a tutorial | E3: IEEE International Conference on QCE | F3: Detailed QAOA walkthrough for Ising problems; applicable to robot task scheduling | G3: Paywalled (IEEE) | H3: DOI: 10.1109/QCE.2019.00033 | I3: ★★★★☆ | J3: Planning & Control | K3: Quantum | L3: Survey | M3: Low | N3: Algorithmic | O3: Scalability and practical hardware advantage | P3: §4 | Q3: To read | S3: §4 | T3: Core
A4: Quantum Optimization | B4: Zhou, L., Wang, S.-T., Choi, S., et al. | C4: 2020 | D4: Quantum approximate optimization algorithm: Performance on near-term devices | E4: Physical Review X, 10(2) | F4: QAOA performance analysis on NISQ devices; realistic expectations for robots | G4: Open Access | H4: https://arxiv.org/abs/1812.07589 | I4: ★★★★★ | J4: Planning & Control | K4: Quantum | L4: Survey | M4: Low | N4: Experimental / algorithmic | O4: Does NISQ-era performance hold at robot-scale instances? | P4: §4 | Q4: To read | S4: §4 | T4: Core
A5: Quantum Optimization | B5: Cerezo, M., Arrasmith, A., Babbush, R., et al. | C5: 2021 | D5: Variational quantum algorithms | E5: Nature Reviews Physics, 3(9) | F5: Comprehensive review of VQE, QAOA, VQC for optimization | G5: Paywalled (Nature); Author PDF available | H5: DOI: 10.1038/s42254-021-00348-9 | I5: ★★★★★ | J5: Foundations | K5: Quantum | L5: Survey | M5: Low | N5: Review | O5: Mostly general VQAs, not robotics-specific validation | P5: §2 | Q5: To read | S5: §4 | T5: Core
A6: Quantum Optimization | B6: Guerreschi, G.G., Carr, J. | C6: 2020 | D6: Solving combinatorial optimization problems using QAOA | E6: arXiv:2001.05824 | F6: QAOA for multi-agent resource allocation; applicable to swarm robotics | G6: Open Access | H6: https://arxiv.org/abs/2001.05824 | I6: ★★★★☆ | J6: Multi-Robot Coordination | K6: Quantum | L6: Survey | M6: Medium | N6: Algorithmic | O6: Scalability to realistic swarm sizes on hardware | P6: §4 | Q6: To read | S6: §4 | T6: Core
A7: Quantum Machine Learning | B7: Biamonte, J., Wittek, P., Pancotti, N., et al. | C7: 2017 | D7: Quantum machine learning | E7: Nature, 549(7671) | F7: Comprehensive QML introduction; robotics applications mentioned | G7: Paywalled (Nature); Author PDF | H7: DOI: 10.1038/nature23474 | I7: ★★★★★ | J7: Learning | K7: Quantum | L7: Survey | M7: Low | N7: Theoretical / experimental | O7: Data encoding and genuine quantum advantage | P7: §5 | Q7: To read | S7: §4, §5 | T7: Core
A8: Quantum Machine Learning | B8: Schuld, M., Killoran, N. | C8: 2022 | D8: Quantum machine learning in feature Hilbert spaces | E8: Nature Communications, 13 | F8: Quantum kernel methods for ML; applicable to robot perception | G8: Open Access | H8: DOI: 10.1038/s41467-022-32464-2 | I8: ★★★★☆ | J8: Learning | K8: Quantum | L8: Survey | M8: Low | N8: Theoretical | O8: Does the feature-map advantage survive on noisy hardware? | P8: §5 | Q8: To read | S8: §4, §5 | T8: Core
A9: Quantum Machine Learning | B9: Havlíček, V., Córcoles, A.D., Temme, K., et al. | C9: 2019 | D9: Supervised learning with quantum-enhanced feature spaces | E9: Nature, 567 | F9: Quantum kernel methods for classification; demonstrated on IBM hardware | G9: Paywalled (Nature) | H9: DOI: 10.1038/s41586-019-0980-2 | I9: ★★★★★ | J9: Learning | K9: Quantum | L9: Survey | M9: Low | N9: Experimental | O9: Small datasets and hardware limitations | P9: §5 | Q9: To read | S9: §4, §5 | T9: Core
A10: Quantum Machine Learning | B10: Henderson, M., Shakya, S., Pradhan, S., Lord, T. | C10: 2020 | D10: Quanvolutional neural networks: powering image recognition with quantum circuits | E10: IEEE Access, 8 | F10: Quantum convolutional layers for robot vision | G10: Open Access | H10: DOI: 10.1109/ACCESS.2020.3034196 | I10: ★★★☆☆ | J10: Perception | K10: Quantum | L10: Survey | M10: Low | N10: Experimental | O10: Whether it scales to real robotic vision | P10: §4 | Q10: To read | S10: §4, §5 | T10: Core
A11: Quantum Machine Learning | B11: Alcazar, A., Datta, A., García-Ginés, M. | C11: 2022 | D11: Quantum machine learning for robot perception | E11: Quantum Machine Intelligence, 4(2) | F11: Survey of QML techniques for robot vision and object detection | G11: Open Access | H11: DOI: 10.1007/s42484-021-00065-7 | I11: ★★★★☆ | J11: Perception | K11: Quantum | L11: Survey | M11: Medium | N11: Survey | O11: Need stronger real-world robotic experiments | P11: §4 | Q11: To read | S11: §4, §5 | T11: Core
A12: Quantum Sensor Fusion | B12: Beran, F., Ivgi, Y., Pastawski, F. | C12: 2022 | D12: Quantum Kalman filtering with NMR and superconducting qubits | E12: arXiv:2206.14118 | F12: First experimental quantum Kalman filter demonstration | G12: Open Access | H12: https://arxiv.org/abs/2206.14118 | I12: ★★★★☆ | J12: Localisation & Navigation | K12: Quantum | L12: Survey | M12: Medium | N12: Experimental | O12: Integration with real robotic sensors | P12: §4 | Q12: To read | S12: §4 | T12: Core
A13: Quantum Sensor Fusion | B13: Cramer, M., Plenio, M.B., Flammia, S.T., et al. | C13: 2010 | D13: Efficient quantum state tomography | E13: Nature Communications, 1 | F13: Quantum state estimation methods; framework for robot belief state | G13: Open Access | H13: DOI: 10.1038/ncomms1147 | I13: ★★★☆☆ | J13: Perception | K13: Quantum | L13: Survey | M13: Low | N13: Theoretical | O13: Mapping to practical robot belief states | P13: §4 | Q13: To read | S13: §4 | T13: Core
... A72: Multi-Robot / Swarm Robotics | B72: Masood, A., Gao, F., Liu, C., et al. | C72: 2018 | D72: A robot SLAM improved by quantum-behaved particle swarm optimization | E72: Mathematical Problems in Engineering, 2018 | F72: Quantum-behaved PSO applied to robot SLAM — concrete quantum-inspired localisation/mapping | G72: Open Access | H72: Math Probl Eng 2018:1596080 | I72: ★★★☆☆ | J72: Localisation & Navigation | K72: Quantum-inspired | L72: Survey | M72: Medium | N72: Algorithmic / experimental | O72: Quantum-behaved PSO is a classical metaheuristic, not quantum computing | P72: §4 | Q72: To read | S72: §7 | T72: Core
A73: Quantum Machine Learning | B73: Liu, Y.-X., Wu, L.-A., Nori, F. | C73: 2022 | D73: Quantum Bayesian inference and machine learning | E73: Nature Physics, 18(11) | F73: Quantum Bayesian inference for probabilistic ML; relevant to robot belief updating | G73: Paywalled | I73: ★★★★☆ | J73: Learning | K73: Quantum | L73: Survey | M73: Medium | N73: Algorithmic / theoretical | O73: Robotic validation and data-loading open | P73: §5 | Q73: To read | R73: Quantum route to Bayesian inference | S73: §4, §5 | T73: Core
A74: Quantum Machine Learning | B74: Tait, A.N., Wu, M.C., Khachaturian, A.H., Prucnal, P.R. | C74: 2018 | D74: Quantum ML in photonic systems | E74: Nature Physics, 14(11) | F74: Photonic quantum ML hardware; context for QML implementations | G74: Paywalled | I74: ★★★☆☆ | J74: Learning | K74: Quantum | L74: Survey | M74: Low | N74: Experimental | O74: Photonic platforms not robot-deployable | P74: §5 | Q74: To read | R74: Hardware context for QML | S74: §4, §5 | T74: Core
A75: Quantum Monte Carlo | B75: Brassard, G., Hoyer, P., Mosca, M., Tapp, A. | C75: 2000 | D75: Quantum amplitude amplification | E75: arXiv:quant-ph/0005055 | F75: Generalises Grover search; core primitive for quantum sampling/search | G75: Open Access | I75: ★★★★☆ | J75: Foundations | K75: Quantum | L75: Survey | M75: Low | N75: Foundational / theoretical | O75: Needs fault-tolerant QC | P75: §4 | Q75: To read | R75: Amplitude amplification primitive | S75: §2, §4 | T75: Core
A76: Quantum Machine Learning | B76: Rebentrost, P., Bromley, T.R., Weedbrook, C., Lloyd, S. | C76: 2014 | D76: Quantum ML in Hilbert spaces | E76: Phys Rev Lett, 113(13) | F76: Quantum SVM / kernel method; robot classification and perception | G76: Open Access | I76: ★★★★☆ | J76: Learning | K76: Quantum | L76: Survey | M76: Low | N76: Theoretical | O76: Data-loading bottleneck | P76: §5 | Q76: To read | R76: Quantum kernel classification | S76: §4, §5 | T76: Core
A77: Quantum Monte Carlo | B77: Ozols, M., Roetteler, M., Roland, J. | C77: 2013 | D77: Quantum rejection sampling | E77: ACM ITCS | F77: Quantum rejection sampling primitive for probabilistic inference | G77: Paywalled | I77: ★★★☆☆ | J77: Foundations | K77: Quantum | L77: Survey | M77: Low | N77: Algorithmic | O77: Practical advantage unclear | P77: §4 | Q77: To read | R77: Sampling primitive | S77: §2, §4 | T77: Core
A78: Quantum ML, RL & Agents | B78: Hohenfeld, H., Heimann, D., Wiebe, F., Kirchner, F. | C78: 2023 | D78: Continuous quantum RL for navigation | E78: Fraunhofer / SciTePress | F78: Hybrid quantum-classical DDPG for continuous navigation; ~200x fewer weights | G78: Open Access | I78: ★★★★☆ | J78: Localisation & Navigation | K78: Quantum | L78: Both | M78: High | N78: Simulation experiment | O78: Simulation only; NISQ feasibility open | P78: §5 | Q78: To read | R78: Continuous-action QRL for navigation | S78: §5 | T78: Core
A79: Quantum Control | B79: Khaneja, N., Reiss, T., Kehlet, C., et al. | C79: 2005 | D79: Optimal control of spin dynamics | E79: J Magnetic Resonance, 172(2) | F79: GRAPE optimal-control algorithm; foundational quantum control pulses | G79: Paywalled | I79: ★★★☆☆ | J79: Planning & Control | K79: Quantum | L79: Survey | M79: Low | N79: Algorithmic | O79: Controls quantum systems, not physical robots | P79: §4 | Q79: To read | R79: GRAPE optimal control | S79: §4 | T79: Core
A80: Quantum Machine Learning | B80: Aaronson, S. | C80: 2015 | D80: Read the fine print | E80: Nature Physics, 11(4) | F80: Critical appraisal of QML speedup caveats (data loading, readout) | G80: Paywalled | I80: ★★★★☆ | J80: Foundations | K80: Quantum | L80: Both | M80: Medium | N80: Review / critique | O80: Tempers quantum-advantage claims | P80: §8 | Q80: To read | R80: Essential QML reality check | S80: §4, §5 | T80: Core
A81: Quantum Cognition (Foundations) | B81: Wang, Z., Solloway, T., Shiffrin, R.M., Busemeyer, J.R. | C81: 2014 | D81: Question order effects reveal quantum nature | E81: PNAS, 111(26) | F81: Strongest large-scale empirical confirmation of QQ-equality across 70 surveys | G81: Open Access | I81: ★★★★★ | J81: Cognition & Decision | K81: Quantum-inspired | L81: Both | M81: High | N81: Empirical | O81: Human data; transfer to robot policies open | P81: §6 | Q81: To read | R81: Landmark order-effect confirmation | S81: §6 | T81: Core
A82: Quantum Cognition (Foundations) | B82: Trueblood, J.S., Busemeyer, J.R. | C82: 2011 | D82: Quantum probability account of order effects | E82: Cognitive Science, 35(8) | F82: Quantum inference model for order/recency effects in inference | G82: Open Access | I82: ★★★★★ | J82: Cognition & Decision | K82: Quantum-inspired | L82: Both | M82: High | N82: Empirical / model | O82: Robot-decision instantiation open | P82: §6 | Q82: To read | R82: Order effects in inference | S82: §6 | T82: Core
A83: Quantum Cognition (Foundations) | B83: Pothos, E.M., Busemeyer, J.R. | C83: 2009 | D83: Quantum probability explanation | E83: Proc Royal Soc B, 276(1665) | F83: Seminal quantum explanation for sure-thing-principle violations | G83: Open Access | I83: ★★★★★ | J83: Cognition & Decision | K83: Quantum-inspired | L83: Both | M83: High | N83: Empirical / model | O83: Robot decision-loop instantiation open | P83: §6 | Q83: To read | R83: Founding decision-fallacy result | S83: §6 | T83: Core
A84: Quantum Cognition (Foundations) | B84: Aerts, D., Sozzo, S. | C84: 2011 | D84: Quantum structure: concepts are entangled | E84: Quantum Interaction 2011 | F84: Entanglement and Bell-inequality violation in concept combinations | G84: Open Access | I84: ★★★★☆ | J84: Cognition & Decision | K84: Quantum-inspired | L84: Both | M84: Medium | N84: Empirical / theoretical | O84: Concept formalism; robotic mapping unclear | P84: §6 | Q84: To read | R84: Entangled concepts | S84: §6 | T84: Core
... A107: Physical AI / Embodied Foundation Models | B107: Ha, D., Schmidhuber, J. | C107: 2018 | D107: World models | E107: NeurIPS 31 | F107: Latent generative world models for planning under uncertainty | G107: Open Access | I107: ★★★★☆ | J107: Learning | K107: Classical baseline | L107: Survey | M107: Medium | N107: Experimental | O107: Classical; embodied-prediction baseline | P107: §9 | Q107: To read | R107: World models baseline | S107: §5 | T107: Core
A108: Quantum Cognition (Foundations) | B108: Aerts, D., Gabora, L., Sozzo, S. | C108: 2013 | D108: Concepts and their dynamics: a quantum-theoretic modeling of human thought | E108: Topics in Cognitive Science, 5(4) | F108: Fock-space model of conceptual combination and emergent meaning | G108: Paywalled (Wiley) | H108: DOI: 10.1111/tops.12042 | I108: ★★★★☆ | J108: Cognition & Decision | K108: Quantum-inspired | L108: Both | M108: Medium | N108: Theoretical | O108: Robot instantiation open | P108: §6 | Q108: To read | R108: Fock-space concept dynamics | S108: §6 | T108: Core
A109: Quantum Cognition (Foundations) | B109: Pothos, E.M., Busemeyer, J.R., Trueblood, J.S. | C109: 2013 | D109: A quantum geometric model of similarity | E109: Psychological Review, 120(3) | F109: Quantum account of asymmetric similarity judgments | G109: Paywalled (APA) | H109: DOI: 10.1037/a0033142 | I109: ★★★☆☆ | J109: Cognition & Decision | K109: Quantum-inspired | L109: Both | M109: Medium | N109: Empirical / model | O109: Similarity in robot perception untested | P109: §6 | Q109: To read | R109: Quantum similarity model | S109: §6 | T109: Core
A110: Quantum Cognition (Foundations) | B110: Waddup, O.J., Yearsley, J.M., Blasiak, P., Pothos, E.M. | C110: 2021 | D110: Sequence effects and quantum models of constructive memory/judgment | E110: Journal of Mathematical Psychology | F110: Extends quantum interference to constructive memory over time | G110: Verify Details | I110: ★★★☆☆ | J110: Cognition & Decision | K110: Quantum-inspired | L110: Both | M110: Medium | N110: Empirical / model | O110: Verify title/venue; robot use open | P110: §6 | Q110: To read | R110: Constructive memory (verify) | S110: §6 | T110: Core
A111: Quantum ML, RL & Agents | B111: Widdows, D., Aboumrad, W., et al. | C111: 2024 | D111: Quantum natural language processing | E111: KI - Künstliche Intelligenz | F111: Review of quantum encodings for embeddings, attention, grammar, uncertainty | G111: Paywalled (Springer); arXiv | H111: DOI: 10.1007/s13218-024-00861-w | I111: ★★★★☆ | J111: Multi-Robot Coordination | K111: Quantum | L111: Both | M111: Medium | N111: Review | O111: Robot language grounding open | P111: §5 | Q111: To read | R111: QNLP survey | S111: §5 | T111: Core
A112: Quantum ML, RL & Agents | B112: Yun, W.J., Park, J., et al. | C112: 2022 | D112: Quantum multi-agent reinforcement learning via variational quantum circuit design | E112: IEEE ICDCS 2022 | F112: Extends VQC-QRL to cooperative multi-agent settings (CTDE) | G112: Paywalled (IEEE); arXiv | H112: arXiv:2203.10443 | I112: ★★★★☆ | J112: Multi-Robot Coordination | K112: Quantum | L112: Both | M112: High | N112: Experimental / algorithmic | O112: Multi-robot hardware scale open | P112: §5 | Q112: To read | R112: Multi-agent QRL | S112: §5 | T112: Core
A113: Quantum ML, RL & Agents | B113: Chen, S.Y.-C., Huang, C.-M., Hsing, C.-W., Goan, H.-S., Kao, Y.-J. | C113: 2022 | D113: Variational quantum reinforcement learning via evolutionary optimization | E113: Machine Learning: Science and Technology, 3(1) | F113: Gradient-free QRL with amplitude encoding for high-dim inputs | G113: Paywalled (IOP) | H113: DOI: 10.1088/2632-2153/ac4559 | I113: ★★★☆☆ | J113: Learning | K113: Quantum | L113: Both | M113: Medium | N113: Experimental / algorithmic | O113: Evolutionary QRL; scaling open | P113: §5 | Q113: To read | R113: Evolutionary QRL | S113: §5 | T113: Core
A114: Quantum Machine Learning | B114: Mitarai, K., Negoro, M., Kitagawa, M., Fujii, K. | C114: 2018 | D114: Quantum circuit learning | E114: Physical Review A, 98 | F114: Introduces parameterized quantum circuits (QCL) for learning tasks | G114: Paywalled (APS); arXiv | H114: DOI: 10.1103/PhysRevA.98.032309 | I114: ★★★★☆ | J114: Learning | K114: Quantum | L114: Survey | M114: Low | N114: Algorithmic / theoretical | O114: Foundational; NISQ scale | P114: §5 | Q114: To read | R114: Quantum circuit learning | S114: §4, §5 | T114: Core
A115: Quantum Machine Learning | B115: Schuld, M., Petruccione, F. | C115: 2021 | D115: Machine Learning with Quantum Computers | E115: Springer | F115: Standard QML textbook for models and quantum feature encodings | G115: Paywalled (book) | H115: DOI: 10.1007/978-3-030-83098-4 | I115: ★★★★☆ | J115: Learning | K115: Quantum | L115: Survey | M115: Low | N115: Reference (book) | O115: Background reference | P115: §5 | Q115: To read | R115: QML textbook | S115: §4, §5 | T115: Core
A116: Quantum Machine Learning | B116: Farhi, E., Neven, H. | C116: 2018 | D116: Classification with quantum neural networks on near-term processors | E116: arXiv:1802.06002 | F116: Early quantum neural network for classification on NISQ devices | G116: Open Access (arXiv) | H116: https://arxiv.org/abs/1802.06002 | I116: ★★★☆☆ | J116: Learning | K116: Quantum | L116: Survey | M116: Low | N116: Algorithmic | O116: NISQ-limited | P116: §5 | Q116: To read | R116: Early QNN classifier | S116: §4, §5 | T116: Core
A117: General Quantum Robotics | B117: Daglarli, E. | C117: 2020 | D117: Computational modeling of prefrontal cortex for meta-cognition of a humanoid robot | E117: IEEE Access, 8 | F117: Classical predecessor to Daglarli 2025; meta-cognitive control (no quantum) | G117: Open Access | H117: researchgate.net/publication/341762348 | I117: ★★★☆☆ | J117: Cognition & Decision | K117: Classical baseline | L117: Survey | M117: Medium | N117: Robot experiment | O117: Classical baseline for the quantum version | P117: §6 | Q117: To read | R117: Meta-cognition predecessor | S117: §4 | T117: Core
A118: General Quantum Robotics | B118: Acuto, A., et al. | C118: 2022 | D118: Variational quantum soft actor-critic for robotic arm control | E118: arXiv | F118: Variational quantum SAC controlling a simulated robotic arm; fewer parameters | G118: Verify Details | I118: ★★★★☆ | J118: Planning & Control | K118: Quantum | L118: Both | M118: High | N118: Simulation experiment | O118: Verify authors/venue; simulation only | P118: §4 | Q118: To read | R118: Quantum SAC arm control (verify) | S118: §4 | T118: Core
A119: General Quantum Robotics | B119: Q-SpiRL (authors to confirm) | C119: 2026 | D119: Q-SpiRL: quantum spiking reinforcement learning for adaptive robot navigation | E119: arXiv:2605.20801 (NYUAD) | F119: Spiking neural nets + quantum RL for adaptive navigation | G119: Verify Details | H119: https://arxiv.org/pdf/2605.20801 | I119: ★★★☆☆ | J119: Localisation & Navigation | K119: Quantum | L119: Both | M119: High | N119: Simulation experiment | O119: Verify authors/venue; preprint | P119: §5 | Q119: To read | R119: Quantum spiking RL (verify) | S119: §4 | T119: Core
A120: Context: Classical Robotics | B120: Thrun, S. | C120: 2000 | D120: Probabilistic algorithms in robotics | E120: AI Magazine, 21(4) | F120: Accessible overview of Bayes-filter perception and localization | G120: Open Access | H120: DOI: 10.1609/aimag.v21i4.1534 | I120: ★★★☆☆ | J120: Foundations | K120: Classical baseline | L120: Survey | M120: Low | N120: Review | O120: Classical baseline | P120: §2 | Q120: To read | R120: Bayes-filter overview | S120: §4 | T120: Context
...

Sheet llm
A1: Category | B1: Author | C1: Year | D1: Title | E1: Venue | F1: Relevance | G1: Status | H1: URL | I1: Importance | J1: Robotics Function | K1: Type | L1: Serves | M1: Gap Relevance | N1: Evidence Type | O1: Open Question / Limitation (for survey) | P1: Outline § | Q1: Read status | R1: Key takeaway / notes
A2: LLM Orchestration & Embodied Agents | B2: Ahn, M., Brohan, A., Brown, N., et al. | C2: 2022 | D2: Do As I Can, Not As I Say: Grounding Language in Robotic Affordances | E2: CoRL 2022 | F2: LLM proposes candidate actions scored by learned affordance value functions — canonical template for an LLM that selects among robot skills/modalities | G2: Open Access (arXiv) | H2: https://arxiv.org/abs/2204.01691 | I2: ★★★★★ | J2: Orchestration | K2: LLM/Agent | L2: Survey + Thesis | M2: High | N2: Experimental | O2: Affordance scores are frozen — no online adaptation of the selector; single-modality skills only | P2: §3 | Q2: To read | R2: SayCan: value-function grounding is the classic baseline your learned orchestrator must beat
A3: LLM Orchestration & Embodied Agents | B3: Huang, W., Xia, F., Xiao, T., et al. | C3: 2022 | D3: Inner Monologue: Embodied Reasoning through Planning with Language Models | E3: CoRL 2022 | F3: Closed-loop LLM planning that ingests success/scene/human feedback — directly analogous to feeding uncertainty signals back to the orchestrator | G3: Open Access (arXiv) | H3: https://arxiv.org/abs/2207.05608 | I3: ★★★★★ | J3: Orchestration | K3: LLM/Agent | L3: Survey + Thesis | M3: High | N3: Experimental | O3: Feedback is textual, not calibrated uncertainty; LLM is frozen (no learning of the fusion policy) | P3: §3 | Q3: To read | R3: Feedback-conditioned replanning; your federated confidence signals are the calibrated version of this
A4: LLM Orchestration & Embodied Agents | B4: Liang, J., Huang, W., Xia, F., et al. | C4: 2022 | D4: Code as Policies: Language Model Programs for Embodied Control | E4: ICRA 2023 | F4: LLM writes executable code that invokes perception/control APIs — mechanistic analog to invoking heterogeneous learning modules | G4: Open Access (arXiv) | H4: https://arxiv.org/abs/2209.07753 | I4: ★★★★☆ | J4: Orchestration | K4: LLM/Agent | L4: Survey | M4: Medium | N4: Experimental | O4: No learning/adaptation of the code-generation policy; brittle to novel APIs | P4: §3 | Q4: To read | R4: Programmatic invocation of skills; contrast with your learned allocation policy
A5: LLM Orchestration & Embodied Agents | B5: Driess, D., Xia, F., Sajjadi, M.S.M., et al. | C5: 2023 | D5: PaLM-E: An Embodied Multimodal Language Model | E5: ICML 2023 | F5: Injects continuous vision/state into an LLM for grounded planning — the multimodal grounding backbone an orchestrator can sit on | G5: Open Access (arXiv) | H5: https://arxiv.org/abs/2303.03378 | I5: ★★★★☆ | J5: Orchestration | K5: LLM/Agent | L5: Survey | M5: Medium | N5: Experimental | O5: 562B params — impossible on edge; no notion of compute-budget allocation | P5: §3 | Q5: To read | R5: Multimodal grounding; motivates why you need a small *local* LLM instead
A6: LLM Orchestration & Embodied Agents | B6: Yao, S., Zhao, J., Yu, D., et al. | C6: 2022 | D6: ReAct: Synergizing Reasoning and Acting in Language Models | E6: ICLR 2023 | F6: Interleaved reason–act loop — the control-loop skeleton for an LLM orchestrator deciding what to invoke next | G6: Open Access (arXiv) | H6: https://arxiv.org/abs/2210.03629 | I6: ★★★★★ | J6: Orchestration | K6: LLM/Agent | L6: Survey + Thesis | M6: High | N6: Experimental | O6: No learned policy over actions; reasoning quality bounded by frozen model | P6: §3 | Q6: To read | R6: Reason-act loop = orchestrator inner loop; you make the acting choice *learned*
A7: LLM Orchestration & Embodied Agents | B7: Schick, T., Dwivedi-Yu, J., Dessì, R., et al. | C7: 2023 | D7: Toolformer: Language Models Can Teach Themselves to Use Tools | E7: NeurIPS 2023 | F7: LLM learns *when* to call which tool via self-supervision — the closest published analog to learning when to invoke each learning modality | G7: Open Access (arXiv) | H7: https://arxiv.org/abs/2302.04761 | I7: ★★★★★ | J7: Orchestration | K7: LLM/Agent | L7: Survey + Thesis | M7: High | N7: Experimental | O7: Offline self-supervision, not online; no uncertainty-driven selection; not embodied | P7: §3 | Q7: To read | R7: Learned tool-invocation; your work makes it online, embodied, uncertainty-gated
A8: LLM Orchestration & Embodied Agents | B8: Shinn, N., Cassano, F., Gopinath, A., et al. | C8: 2023 | D8: Reflexion: Language Agents with Verbal Reinforcement Learning | E8: NeurIPS 2023 | F8: Agent improves via reflective memory over episodes — a training-free precursor to your online-improving orchestrator | G8: Open Access (arXiv) | H8: https://arxiv.org/abs/2303.11366 | I8: ★★★☆☆ | J8: Orchestration | K8: LLM/Agent | L8: Survey | M8: Medium | N8: Experimental | O8: Improvement is in-context memory only — no weight updates; forgets across resets | P8: §3 | Q8: To read | R8: Verbal self-improvement vs your LoRA-based weight-level improvement
A9: LLM Orchestration & Embodied Agents | B9: Wang, G., Xie, Y., Jiang, Y., et al. | C9: 2023 | D9: Voyager: An Open-Ended Embodied Agent with Large Language Models | E9: TMLR 2024 | F9: Lifelong agent that grows a reusable skill library — parallels composing/reusing learning modes over a robot's lifetime | G9: Open Access (arXiv) | H9: https://arxiv.org/abs/2305.16291 | I9: ★★★☆☆ | J9: Orchestration | K9: LLM/Agent | L9: Survey | M9: Medium | N9: Experimental | O9: Simulation (Minecraft) only; relies on GPT-4 API — not edge-deployable | P9: §3 | Q9: To read | R9: Open-ended skill acquisition; your contribution is doing it on constrained hardware
A10: LLM Orchestration & Embodied Agents | B10: Singh, I., Blukis, V., Mousavian, A., et al. | C10: 2022 | D10: ProgPrompt: Generating Situated Robot Task Plans using Large Language Models | E10: ICRA 2023 | F10: Programmatic LLM prompting for situated task plans — plan-representation reference | G10: Open Access (arXiv) | H10: https://arxiv.org/abs/2209.11302 | I10: ★★★☆☆ | J10: Orchestration | K10: LLM/Agent | L10: Survey | M10: Low | N10: Experimental | O10: Open-loop; no feedback, no adaptation | P10: §3 | Q10: To read | R10: Plan-as-program representation; minor baseline
A11: LLM Orchestration & Embodied Agents | B11: Huang, W., Wang, C., Zhang, R., et al. | C11: 2023 | D11: VoxPoser: Composable 3D Value Maps for Robotic Manipulation with Language Models | E11: CoRL 2023 | F11: LLM composes 3D value maps zero-shot to drive control — example of LLM orchestrating perception+planning modules | G11: Open Access (arXiv) | H11: https://arxiv.org/abs/2307.05973 | I11: ★★★☆☆ | J11: Orchestration | K11: LLM/Agent | L11: Survey | M11: Medium | N11: Experimental | O11: Zero-shot, no learning; assumes reliable perception (no uncertainty gating) | P11: §3 | Q11: To read | R11: LLM-composed value maps; contrast with learned modality fusion
A12: LLM Orchestration & Embodied Agents | B12: Yu, W., Gileadi, N., Fu, C., et al. | C12: 2023 | D12: Language to Rewards for Robotic Skill Synthesis | E12: CoRL 2023 | F12: LLM emits reward specifications that drive RL — bridge between LLM orchestration and the RL modality | G12: Open Access (arXiv) | H12: https://arxiv.org/abs/2306.08647 | I12: ★★★☆☆ | J12: Orchestration | K12: LLM/Agent | L12: Survey | M12: Medium | N12: Experimental | O12: One-directional (LLM→RL); no feedback of RL uncertainty back to the LLM | P12: §3 | Q12: To read | R12: LLM→reward pipeline; your loop is bidirectional via policy-variance signals
A13: LLM Orchestration & Embodied Agents | B13: Huang, W., Abbeel, P., Pathak, D., Mordatch, I. | C13: 2022 | D13: Language Models as Zero-Shot Planners: Extracting Actionable Knowledge for Embodied Agents | E13: ICML 2022 | F13: First to show a frozen LLM emits executable embodied plans zero-shot — the canonical frozen-LLM coordination baseline your learned orchestrator must beat | G13: Open Access (arXiv) | H13: https://arxiv.org/abs/2201.07207 | I13: ★★★★★ | J13: Orchestration | K13: LLM/Agent | L13: Survey + Thesis | M13: High | N13: Experimental | O13: No grounding, feedback, or learning — open-loop and frozen | P13: §3 | Q13: To read | R13: Origin of LLM-as-planner; the exact frozen baseline in your comparison
... A102: Hardware, Benchmarks & Mobile Manipulation | B102: James, S., Ma, Z., Arrojo, D.R., Davison, A.J. | C102: 2020 | D102: RLBench: The Robot Learning Benchmark & Learning Environment | E102: IEEE RA-L 5(2) | F102: Large multi-task manipulation benchmark — standard evaluation suite to situate results | G102: Open Access (arXiv) | H102: https://arxiv.org/abs/1909.12271 | I102: ★★★☆☆ | J102: Hardware/Benchmark | K102: Hardware | L102: Survey | M102: Medium | N102: Experimental | O102: Simulation-only; fixed-arm, not mobile | P102: §13 | Q102: To read | R102: Multi-task benchmark comparator

Sheet Survey 1 Papers
A1: Category | B1: Author | C1: Year | D1: Title | E1: Venue | F1: Relevance | G1: Status | H1: URL | I1: Importance | J1: Robotics Function | K1: Type | L1: Serves | M1: Gap Relevance | N1: Evidence Type | O1: Open Question / Limitation (for survey) | P1: Outline § | Q1: Read status | R1: Key takeaway / notes | S1: Read for Survey § | T1: Survey read role | U1: Final outline § | V1: Curation note | W1: In other survey?
A2: Quantum Optimization | B2: Farhi, E., Goldstone, J., Gutmann, S. | C2: 2014 | D2: A Quantum Approximate Optimization Algorithm | E2: arXiv:1411.4028 | F2: Foundational QAOA paper; introduces variational quantum circuits for combinatorial optimization | G2: Open Access | H2: https://arxiv.org/abs/1411.4028 | I2: ★★★★★ | J2: Planning & Control | K2: Quantum | L2: Survey | M2: Low | N2: Algorithmic / theoretical | O2: Does it outperform classical optimization for realistic robot problems? | P2: §4 | Q2: To read | S2: §4 | T2: Core | U2: 3.1 | W2: =IF(COUNTIF('Survey 2 Papers'!$D:$D,D2)>0,"Shared with S2","Unique") -> Unique
A3: Quantum Optimization | B3: Hadfield, S., Wang, Z., O'Gorman, B., et al. | C3: 2019 | D3: From the Quantum Approximate Optimization Algorithm to a Quantum Alternating Operator Ansatz | E3: Algorithms, 12(2) | F3: Detailed QAOA walkthrough for Ising problems; applicable to robot task scheduling | G3: Paywalled (IEEE) | H3: https://arxiv.org/abs/1709.03489 | I3: ★★★★☆ | J3: Planning & Control | K3: Quantum | L3: Survey | M3: Low | N3: Algorithmic | O3: Scalability and practical hardware advantage | P3: §4 | Q3: To read | S3: §4 | T3: Core | U3: 3.1 | V3: Citation corrected (title/venue) | W3: =IF(COUNTIF('Survey 2 Papers'!$D:$D,D3)>0,"Shared with S2","Unique") -> Unique
A4: Quantum Optimization | B4: Zhou, L., Wang, S.-T., Choi, S., et al. | C4: 2020 | D4: Quantum approximate optimization algorithm: Performance on near-term devices | E4: Physical Review X, 10(2) | F4: QAOA performance analysis on NISQ devices; realistic expectations for robots | G4: Open Access | H4: https://arxiv.org/abs/1812.07589 | I4: ★★★★★ | J4: Planning & Control | K4: Quantum | L4: Survey | M4: Low | N4: Experimental / algorithmic | O4: Does NISQ-era performance hold at robot-scale instances? | P4: §4 | Q4: To read | S4: §4 | T4: Core | U4: 3.1 | W4: =IF(COUNTIF('Survey 2 Papers'!$D:$D,D4)>0,"Shared with S2","Unique") -> Unique
A5: Quantum Optimization | B5: Cerezo, M., Arrasmith, A., Babbush, R., et al. | C5: 2021 | D5: Variational quantum algorithms | E5: Nature Reviews Physics, 3(9) | F5: Comprehensive review of VQE, QAOA, VQC for optimization | G5: Paywalled (Nature); Author PDF available | H5: DOI: 10.1038/s42254-021-00348-9 | I5: ★★★★★ | J5: Foundations | K5: Quantum | L5: Survey | M5: Low | N5: Review | O5: Mostly general VQAs, not robotics-specific validation | P5: §2 | Q5: To read | S5: §4 | T5: Core | U5: 3.2 | W5: =IF(COUNTIF('Survey 2 Papers'!$D:$D,D5)>0,"Shared with S2","Unique") -> Unique
A6: Quantum Machine Learning | B6: Biamonte, J., Wittek, P., Pancotti, N., et al. | C6: 2017 | D6: Quantum machine learning | E6: Nature, 549(7671) | F6: Comprehensive QML introduction; robotics applications mentioned | G6: Paywalled (Nature); Author PDF | H6: DOI: 10.1038/nature23474 | I6: ★★★★★ | J6: Learning | K6: Quantum | L6: Survey | M6: Low | N6: Theoretical / experimental | O6: Data encoding and genuine quantum advantage | P6: §5 | Q6: To read | S6: §4, §5 | T6: Core | U6: 3.2 | W6: =IF(COUNTIF('Survey 2 Papers'!$D:$D,D6)>0,"Shared with S2","Unique") -> Shared with S2
A7: Quantum Machine Learning | B7: Schuld, M., Killoran, N. | C7: 2019 | D7: Quantum machine learning in feature Hilbert spaces | E7: Physical Review Letters, 122(4) | F7: Quantum kernel methods for ML; applicable to robot perception | G7: Open Access | H7: https://arxiv.org/abs/1803.07128 | I7: ★★★★☆ | J7: Learning | K7: Quantum | L7: Survey | M7: Low | N7: Theoretical | O7: Does the feature-map advantage survive on noisy hardware? | P7: §5 | Q7: To read | S7: §4, §5 | T7: Core | U7: 3.2 | V7: Citation corrected (year/venue) | W7: =IF(COUNTIF('Survey 2 Papers'!$D:$D,D7)>0,"Shared with S2","Unique") -> Shared with S2
A8: Quantum Machine Learning | B8: Havlíček, V., Córcoles, A.D., Temme, K., et al. | C8: 2019 | D8: Supervised learning with quantum-enhanced feature spaces | E8: Nature, 567 | F8: Quantum kernel methods for classification; demonstrated on IBM hardware | G8: Paywalled (Nature) | H8: DOI: 10.1038/s41586-019-0980-2 | I8: ★★★★★ | J8: Learning | K8: Quantum | L8: Survey | M8: Low | N8: Experimental | O8: Small datasets and hardware limitations | P8: §5 | Q8: To read | S8: §4, §5 | T8: Core | U8: 3.2 | W8: =IF(COUNTIF('Survey 2 Papers'!$D:$D,D8)>0,"Shared with S2","Unique") -> Unique
A9: Quantum Machine Learning | B9: Henderson, M., Shakya, S., Pradhan, S., Lord, T. | C9: 2020 | D9: Quanvolutional neural networks: powering image recognition with quantum circuits | E9: Quantum Machine Intelligence, 2(1) | F9: Quantum convolutional layers for robot vision | G9: Open Access | H9: DOI: 10.1007/s42484-020-00012-y | I9: ★★★☆☆ | J9: Perception | K9: Quantum | L9: Survey | M9: Low | N9: Experimental | O9: Whether it scales to real robotic vision | P9: §4 | Q9: To read | S9: §4, §5 | T9: Core | U9: 3.2 | V9: Venue corrected | W9: =IF(COUNTIF('Survey 2 Papers'!$D:$D,D9)>0,"Shared with S2","Unique") -> Unique
A10: Quantum Anomaly Detection | B10: Lloyd, S., Mohseni, M., Rebentrost, P. | C10: 2014 | D10: Quantum algorithms for supervised and unsupervised machine learning | E10: arXiv:1307.0411 | F10: Foundational paper on quantum clustering and anomaly detection | G10: Open Access | H10: https://arxiv.org/abs/1307.0411 | I10: ★★★★☆ | J10: Learning | K10: Quantum | L10: Survey | M10: Medium | N10: Algorithmic | O10: Limited robotic-system validation | P10: §5 | Q10: To read | S10: §4 | T10: Core | U10: 3.2 | W10: =IF(COUNTIF('Survey 2 Papers'!$D:$D,D10)>0,"Shared with S2","Unique") -> Unique
A11: Quantum Monte Carlo | B11: Grover, L.K. | C11: 1996 | D11: A fast quantum mechanical algorithm for database search | E11: ACM Symposium on Theory of Computing | F11: Foundational Grover's algorithm for quantum search/sampling | G11: Open Access | H11: https://arxiv.org/abs/quant-ph/9605043 | I11: ★★★★★ | J11: Foundations | K11: Quantum | L11: Survey | M11: Low | N11: Foundational / theoretical | O11: Requires fault-tolerant QC for many robot formulations | P11: §2 | Q11: To read | S11: §2, §4 | T11: Core | U11: 1.3 Era 2; 3.4 | W11: =IF(COUNTIF('Survey 2 Papers'!$D:$D,D11)>0,"Shared with S2","Unique") -> Unique
A12: Quantum Monte Carlo | B12: Montanaro, A. | C12: 2015 | D12: Quantum speedup of Monte Carlo methods | E12: Proceedings of the Royal Society A, 471 | F12: Theoretical √N speedup for quantum Monte Carlo sampling | G12: Open Access | H12: DOI: 10.1098/rspa.2015.0301 | I12: ★★★★☆ | J12: Localisation & Navigation | K12: Quantum | L12: Survey | M12: Low | N12: Theoretical | O12: Requires fault-tolerant quantum computing in many formulations | P12: §4 | Q12: To read | S12: §2, §4 | T12: Core | U12: 3.4 | W12: =IF(COUNTIF('Survey 2 Papers'!$D:$D,D12)>0,"Shared with S2","Unique") -> Unique
A13: Quantum Monte Carlo | B13: Wiebe, N., Kapoor, A., Svore, K.M. | C13: 2015 | D13: Quantum algorithms for nearest-neighbor methods | E13: Quantum Information & Computation, 15(3-4) | F13: Quantum nearest-neighbor via Grover; foundation for particle filtering | G13: Paywalled (QIC); arXiv available | H13: https://arxiv.org/abs/1401.2142 | I13: ★★★☆☆ | J13: Localisation & Navigation | K13: Quantum | L13: Survey | M13: Medium | N13: Theoretical | O13: Practical quantum advantage unclear | P13: §4 | Q13: To read | S13: §2, §4 | T13: Core | U13: 3.4 | W13: =IF(COUNTIF('Survey 2 Papers'!$D:$D,D13)>0,"Shared with S2","Unique") -> Unique
A14: Quantum Linear Algebra | B14: Harrow, A.W., Hassidim, A., Lloyd, S. | C14: 2009 | D14: Quantum algorithm for linear systems of equations | E14: Physical Review Letters, 103(15) | F14: Foundational HHL algorithm for solving linear systems; potential for inverse kinematics | G14: Open Access | H14: https://arxiv.org/abs/0811.3171 | I14: ★★★★☆ | J14: Planning & Control | K14: Quantum | L14: Survey | M14: Medium | N14: Theoretical | O14: Input/output and data-loading bottlenecks | P14: §4 | Q14: To read | S14: §2, §4 | T14: Core | U14: 1.3 Era 3 | V14: Title corrected | W14: =IF(COUNTIF('Survey 2 Papers'!$D:$D,D14)>0,"Shared with S2","Unique") -> Unique
A15: Quantum Graph Algorithms | B15: Barkoutsos, P.K., Nannicini, G., Robert, A., et al. | C15: 2020 | D15: Improving variational quantum optimization using CVaR | E15: Quantum, 4 | F15: QAOA for MaxCut with improved convergence; robot task scheduling | G15: Open Access | H15: DOI: 10.22331/q-2020-04-20-256 | I15: ★★★★☆ | J15: Planning & Control | K15: Quantum | L15: Survey | M15: Low | N15: Experimental / algorithmic | O15: Still constrained by NISQ hardware | P15: §4 | Q15: To read | S15: §2, §4 | T15: Core | U15: 3.1 | W15: =IF(COUNTIF('Survey 2 Papers'!$D:$D,D15)>0,"Shared with S2","Unique") -> Unique
